[2023-02-23T01:41:59.235+0000] {taskinstance.py:1083} INFO - Dependencies all met for <TaskInstance: predictit_dag.process_json scheduled__2023-02-22T00:00:00+00:00 [queued]>
[2023-02-23T01:41:59.247+0000] {taskinstance.py:1083} INFO - Dependencies all met for <TaskInstance: predictit_dag.process_json scheduled__2023-02-22T00:00:00+00:00 [queued]>
[2023-02-23T01:41:59.247+0000] {taskinstance.py:1279} INFO - 
--------------------------------------------------------------------------------
[2023-02-23T01:41:59.248+0000] {taskinstance.py:1280} INFO - Starting attempt 1 of 2
[2023-02-23T01:41:59.248+0000] {taskinstance.py:1281} INFO - 
--------------------------------------------------------------------------------
[2023-02-23T01:41:59.259+0000] {taskinstance.py:1300} INFO - Executing <Task(PythonOperator): process_json> on 2023-02-22 00:00:00+00:00
[2023-02-23T01:41:59.263+0000] {standard_task_runner.py:55} INFO - Started process 9233 to run task
[2023-02-23T01:41:59.264+0000] {standard_task_runner.py:82} INFO - Running: ['***', 'tasks', 'run', 'predictit_dag', 'process_json', 'scheduled__2023-02-22T00:00:00+00:00', '--job-id', '638', '--raw', '--subdir', 'DAGS_FOLDER/predictit_dag.py', '--cfg-path', '/tmp/tmpq1iw9v28']
[2023-02-23T01:41:59.265+0000] {standard_task_runner.py:83} INFO - Job 638: Subtask process_json
[2023-02-23T01:41:59.313+0000] {task_command.py:388} INFO - Running <TaskInstance: predictit_dag.process_json scheduled__2023-02-22T00:00:00+00:00 [running]> on host 9e0dc30811b3
[2023-02-23T01:41:59.377+0000] {taskinstance.py:1509} INFO - Exporting the following env vars:
AIRFLOW_CTX_DAG_EMAIL=kyunlee@yahoo.com
AIRFLOW_CTX_DAG_OWNER=kyun
AIRFLOW_CTX_DAG_ID=predictit_dag
AIRFLOW_CTX_TASK_ID=process_json
AIRFLOW_CTX_EXECUTION_DATE=2023-02-22T00:00:00+00:00
AIRFLOW_CTX_TRY_NUMBER=1
AIRFLOW_CTX_DAG_RUN_ID=scheduled__2023-02-22T00:00:00+00:00
[2023-02-23T01:42:02.828+0000] {taskinstance.py:1768} ERROR - Task failed with exception
Traceback (most recent call last):
  File "/home/airflow/.local/lib/python3.7/site-packages/boto3/s3/transfer.py", line 292, in upload_file
    future.result()
  File "/home/airflow/.local/lib/python3.7/site-packages/s3transfer/futures.py", line 103, in result
    return self._coordinator.result()
  File "/home/airflow/.local/lib/python3.7/site-packages/s3transfer/futures.py", line 266, in result
    raise self._exception
  File "/home/airflow/.local/lib/python3.7/site-packages/s3transfer/tasks.py", line 139, in __call__
    return self._execute_main(kwargs)
  File "/home/airflow/.local/lib/python3.7/site-packages/s3transfer/tasks.py", line 162, in _execute_main
    return_value = self._main(**kwargs)
  File "/home/airflow/.local/lib/python3.7/site-packages/s3transfer/upload.py", line 758, in _main
    client.put_object(Bucket=bucket, Key=key, Body=body, **extra_args)
  File "/home/airflow/.local/lib/python3.7/site-packages/botocore/client.py", line 530, in _api_call
    return self._make_api_call(operation_name, kwargs)
  File "/home/airflow/.local/lib/python3.7/site-packages/botocore/client.py", line 960, in _make_api_call
    raise error_class(parsed_response, operation_name)
botocore.exceptions.ClientError: An error occurred (RequestTimeTooSkewed) when calling the PutObject operation: The difference between the request time and the current time is too large.

During handling of the above exception, another exception occurred:

Traceback (most recent call last):
  File "/home/airflow/.local/lib/python3.7/site-packages/airflow/operators/python.py", line 175, in execute
    return_value = self.execute_callable()
  File "/home/airflow/.local/lib/python3.7/site-packages/airflow/operators/python.py", line 192, in execute_callable
    return self.python_callable(*self.op_args, **self.op_kwargs)
  File "/opt/airflow/dags/json_scraper.py", line 15, in json_scraper
    s3.upload_file(file_name, bucket_name, f"predict_files/{file_name}")
  File "/home/airflow/.local/lib/python3.7/site-packages/boto3/s3/inject.py", line 148, in upload_file
    callback=Callback,
  File "/home/airflow/.local/lib/python3.7/site-packages/boto3/s3/transfer.py", line 300, in upload_file
    filename, '/'.join([bucket, key]), e
boto3.exceptions.S3UploadFailedError: Failed to upload json_file.json to ***bucketforetlproject/predict_files/json_file.json: An error occurred (RequestTimeTooSkewed) when calling the PutObject operation: The difference between the request time and the current time is too large.
[2023-02-23T01:42:02.841+0000] {taskinstance.py:1323} INFO - Marking task as UP_FOR_RETRY. dag_id=predictit_dag, task_id=process_json, execution_date=20230222T000000, start_date=20230223T014159, end_date=20230223T014202
[2023-02-23T01:42:02.851+0000] {standard_task_runner.py:105} ERROR - Failed to execute job 638 for task process_json (Failed to upload json_file.json to ***bucketforetlproject/predict_files/json_file.json: An error occurred (RequestTimeTooSkewed) when calling the PutObject operation: The difference between the request time and the current time is too large.; 9233)
[2023-02-23T01:42:02.886+0000] {local_task_job.py:208} INFO - Task exited with return code 1
[2023-02-23T01:42:02.901+0000] {taskinstance.py:2578} INFO - 0 downstream tasks scheduled from follow-on schedule check
