[2023-02-20T06:05:38.806+0000] {taskinstance.py:1083} INFO - Dependencies all met for <TaskInstance: predictit_dag.process_json manual__2023-02-20T05:55:34.837235+00:00 [queued]>
[2023-02-20T06:05:38.814+0000] {taskinstance.py:1083} INFO - Dependencies all met for <TaskInstance: predictit_dag.process_json manual__2023-02-20T05:55:34.837235+00:00 [queued]>
[2023-02-20T06:05:38.815+0000] {taskinstance.py:1279} INFO - 
--------------------------------------------------------------------------------
[2023-02-20T06:05:38.815+0000] {taskinstance.py:1280} INFO - Starting attempt 2 of 2
[2023-02-20T06:05:38.815+0000] {taskinstance.py:1281} INFO - 
--------------------------------------------------------------------------------
[2023-02-20T06:05:38.827+0000] {taskinstance.py:1300} INFO - Executing <Task(PythonOperator): process_json> on 2023-02-20 05:55:34.837235+00:00
[2023-02-20T06:05:38.831+0000] {standard_task_runner.py:55} INFO - Started process 4104 to run task
[2023-02-20T06:05:38.833+0000] {standard_task_runner.py:82} INFO - Running: ['***', 'tasks', 'run', 'predictit_dag', 'process_json', 'manual__2023-02-20T05:55:34.837235+00:00', '--job-id', '552', '--raw', '--subdir', 'DAGS_FOLDER/predictit_dag.py', '--cfg-path', '/tmp/tmp8pa29z51']
[2023-02-20T06:05:38.834+0000] {standard_task_runner.py:83} INFO - Job 552: Subtask process_json
[2023-02-20T06:05:38.935+0000] {task_command.py:388} INFO - Running <TaskInstance: predictit_dag.process_json manual__2023-02-20T05:55:34.837235+00:00 [running]> on host 9e0dc30811b3
[2023-02-20T06:05:38.982+0000] {taskinstance.py:1509} INFO - Exporting the following env vars:
AIRFLOW_CTX_DAG_EMAIL=kyunlee@yahoo.com
AIRFLOW_CTX_DAG_OWNER=kyun
AIRFLOW_CTX_DAG_ID=predictit_dag
AIRFLOW_CTX_TASK_ID=process_json
AIRFLOW_CTX_EXECUTION_DATE=2023-02-20T05:55:34.837235+00:00
AIRFLOW_CTX_TRY_NUMBER=2
AIRFLOW_CTX_DAG_RUN_ID=manual__2023-02-20T05:55:34.837235+00:00
[2023-02-20T06:05:39.389+0000] {taskinstance.py:1768} ERROR - Task failed with exception
Traceback (most recent call last):
  File "/home/airflow/.local/lib/python3.7/site-packages/airflow/operators/python.py", line 175, in execute
    return_value = self.execute_callable()
  File "/home/airflow/.local/lib/python3.7/site-packages/airflow/operators/python.py", line 192, in execute_callable
    return self.python_callable(*self.op_args, **self.op_kwargs)
  File "/opt/airflow/dags/json_scraper.py", line 14, in json_scraper
    s3.upload_file(file_name, bucket_name, f"predict_files/{file_name}")
  File "/home/airflow/.local/lib/python3.7/site-packages/boto3/s3/inject.py", line 148, in upload_file
    callback=Callback,
  File "/home/airflow/.local/lib/python3.7/site-packages/boto3/s3/transfer.py", line 292, in upload_file
    future.result()
  File "/home/airflow/.local/lib/python3.7/site-packages/s3transfer/futures.py", line 103, in result
    return self._coordinator.result()
  File "/home/airflow/.local/lib/python3.7/site-packages/s3transfer/futures.py", line 266, in result
    raise self._exception
  File "/home/airflow/.local/lib/python3.7/site-packages/s3transfer/tasks.py", line 139, in __call__
    return self._execute_main(kwargs)
  File "/home/airflow/.local/lib/python3.7/site-packages/s3transfer/tasks.py", line 162, in _execute_main
    return_value = self._main(**kwargs)
  File "/home/airflow/.local/lib/python3.7/site-packages/s3transfer/upload.py", line 758, in _main
    client.put_object(Bucket=bucket, Key=key, Body=body, **extra_args)
  File "/home/airflow/.local/lib/python3.7/site-packages/botocore/client.py", line 530, in _api_call
    return self._make_api_call(operation_name, kwargs)
  File "/home/airflow/.local/lib/python3.7/site-packages/botocore/client.py", line 944, in _make_api_call
    operation_model, request_dict, request_context
  File "/home/airflow/.local/lib/python3.7/site-packages/botocore/client.py", line 966, in _make_request
    return self._endpoint.make_request(operation_model, request_dict)
  File "/home/airflow/.local/lib/python3.7/site-packages/botocore/endpoint.py", line 119, in make_request
    return self._send_request(request_dict, operation_model)
  File "/home/airflow/.local/lib/python3.7/site-packages/botocore/endpoint.py", line 198, in _send_request
    request = self.create_request(request_dict, operation_model)
  File "/home/airflow/.local/lib/python3.7/site-packages/botocore/endpoint.py", line 137, in create_request
    operation_name=operation_model.name,
  File "/home/airflow/.local/lib/python3.7/site-packages/botocore/hooks.py", line 412, in emit
    return self._emitter.emit(aliased_event_name, **kwargs)
  File "/home/airflow/.local/lib/python3.7/site-packages/botocore/hooks.py", line 256, in emit
    return self._emit(event_name, kwargs)
  File "/home/airflow/.local/lib/python3.7/site-packages/botocore/hooks.py", line 239, in _emit
    response = handler(**kwargs)
  File "/home/airflow/.local/lib/python3.7/site-packages/botocore/signers.py", line 105, in handler
    return self.sign(operation_name, request)
  File "/home/airflow/.local/lib/python3.7/site-packages/botocore/signers.py", line 189, in sign
    auth.add_auth(request)
  File "/home/airflow/.local/lib/python3.7/site-packages/botocore/auth.py", line 418, in add_auth
    raise NoCredentialsError()
botocore.exceptions.NoCredentialsError: Unable to locate credentials
[2023-02-20T06:05:39.399+0000] {taskinstance.py:1323} INFO - Marking task as FAILED. dag_id=predictit_dag, task_id=process_json, execution_date=20230220T055534, start_date=20230220T060538, end_date=20230220T060539
[2023-02-20T06:05:39.411+0000] {warnings.py:110} WARNING - /home/***/.local/lib/python3.7/site-packages/***/utils/email.py:152: RemovedInAirflow3Warning: Fetching SMTP credentials from configuration variables will be deprecated in a future release. Please set credentials using a connection instead.
  send_mime_email(e_from=mail_from, e_to=recipients, mime_msg=msg, conn_id=conn_id, dryrun=dryrun)

[2023-02-20T06:05:39.411+0000] {configuration.py:663} WARNING - section/key [smtp/smtp_user] not found in config
[2023-02-20T06:05:39.411+0000] {email.py:268} INFO - Email alerting: attempt 1
[2023-02-20T06:05:39.416+0000] {configuration.py:663} WARNING - section/key [smtp/smtp_user] not found in config
[2023-02-20T06:05:39.416+0000] {email.py:268} INFO - Email alerting: attempt 1
[2023-02-20T06:05:39.416+0000] {taskinstance.py:1831} ERROR - Failed to send email to: ['kyunlee@yahoo.com']
Traceback (most recent call last):
  File "/home/airflow/.local/lib/python3.7/site-packages/airflow/models/taskinstance.py", line 1374, in _run_raw_task
    self._execute_task_with_callbacks(context, test_mode)
  File "/home/airflow/.local/lib/python3.7/site-packages/airflow/models/taskinstance.py", line 1520, in _execute_task_with_callbacks
    result = self._execute_task(context, task_orig)
  File "/home/airflow/.local/lib/python3.7/site-packages/airflow/models/taskinstance.py", line 1581, in _execute_task
    result = execute_callable(context=context)
  File "/home/airflow/.local/lib/python3.7/site-packages/airflow/operators/python.py", line 175, in execute
    return_value = self.execute_callable()
  File "/home/airflow/.local/lib/python3.7/site-packages/airflow/operators/python.py", line 192, in execute_callable
    return self.python_callable(*self.op_args, **self.op_kwargs)
  File "/opt/airflow/dags/json_scraper.py", line 14, in json_scraper
    s3.upload_file(file_name, bucket_name, f"predict_files/{file_name}")
  File "/home/airflow/.local/lib/python3.7/site-packages/boto3/s3/inject.py", line 148, in upload_file
    callback=Callback,
  File "/home/airflow/.local/lib/python3.7/site-packages/boto3/s3/transfer.py", line 292, in upload_file
    future.result()
  File "/home/airflow/.local/lib/python3.7/site-packages/s3transfer/futures.py", line 103, in result
    return self._coordinator.result()
  File "/home/airflow/.local/lib/python3.7/site-packages/s3transfer/futures.py", line 266, in result
    raise self._exception
  File "/home/airflow/.local/lib/python3.7/site-packages/s3transfer/tasks.py", line 139, in __call__
    return self._execute_main(kwargs)
  File "/home/airflow/.local/lib/python3.7/site-packages/s3transfer/tasks.py", line 162, in _execute_main
    return_value = self._main(**kwargs)
  File "/home/airflow/.local/lib/python3.7/site-packages/s3transfer/upload.py", line 758, in _main
    client.put_object(Bucket=bucket, Key=key, Body=body, **extra_args)
  File "/home/airflow/.local/lib/python3.7/site-packages/botocore/client.py", line 530, in _api_call
    return self._make_api_call(operation_name, kwargs)
  File "/home/airflow/.local/lib/python3.7/site-packages/botocore/client.py", line 944, in _make_api_call
    operation_model, request_dict, request_context
  File "/home/airflow/.local/lib/python3.7/site-packages/botocore/client.py", line 966, in _make_request
    return self._endpoint.make_request(operation_model, request_dict)
  File "/home/airflow/.local/lib/python3.7/site-packages/botocore/endpoint.py", line 119, in make_request
    return self._send_request(request_dict, operation_model)
  File "/home/airflow/.local/lib/python3.7/site-packages/botocore/endpoint.py", line 198, in _send_request
    request = self.create_request(request_dict, operation_model)
  File "/home/airflow/.local/lib/python3.7/site-packages/botocore/endpoint.py", line 137, in create_request
    operation_name=operation_model.name,
  File "/home/airflow/.local/lib/python3.7/site-packages/botocore/hooks.py", line 412, in emit
    return self._emitter.emit(aliased_event_name, **kwargs)
  File "/home/airflow/.local/lib/python3.7/site-packages/botocore/hooks.py", line 256, in emit
    return self._emit(event_name, kwargs)
  File "/home/airflow/.local/lib/python3.7/site-packages/botocore/hooks.py", line 239, in _emit
    response = handler(**kwargs)
  File "/home/airflow/.local/lib/python3.7/site-packages/botocore/signers.py", line 105, in handler
    return self.sign(operation_name, request)
  File "/home/airflow/.local/lib/python3.7/site-packages/botocore/signers.py", line 189, in sign
    auth.add_auth(request)
  File "/home/airflow/.local/lib/python3.7/site-packages/botocore/auth.py", line 418, in add_auth
    raise NoCredentialsError()
botocore.exceptions.NoCredentialsError: Unable to locate credentials

During handling of the above exception, another exception occurred:

Traceback (most recent call last):
  File "/home/airflow/.local/lib/python3.7/site-packages/airflow/models/taskinstance.py", line 2231, in email_alert
    send_email(task.email, subject, html_content)
  File "/home/airflow/.local/lib/python3.7/site-packages/airflow/utils/email.py", line 91, in send_email
    **kwargs,
  File "/home/airflow/.local/lib/python3.7/site-packages/airflow/utils/email.py", line 152, in send_email_smtp
    send_mime_email(e_from=mail_from, e_to=recipients, mime_msg=msg, conn_id=conn_id, dryrun=dryrun)
  File "/home/airflow/.local/lib/python3.7/site-packages/airflow/utils/email.py", line 270, in send_mime_email
    smtp_conn = _get_smtp_connection(smtp_host, smtp_port, smtp_timeout, smtp_ssl)
  File "/home/airflow/.local/lib/python3.7/site-packages/airflow/utils/email.py", line 317, in _get_smtp_connection
    else smtplib.SMTP(host=host, port=port, timeout=timeout)
  File "/usr/local/lib/python3.7/smtplib.py", line 251, in __init__
    (code, msg) = self.connect(host, port)
  File "/usr/local/lib/python3.7/smtplib.py", line 336, in connect
    self.sock = self._get_socket(host, port, self.timeout)
  File "/usr/local/lib/python3.7/smtplib.py", line 307, in _get_socket
    self.source_address)
  File "/usr/local/lib/python3.7/socket.py", line 728, in create_connection
    raise err
  File "/usr/local/lib/python3.7/socket.py", line 716, in create_connection
    sock.connect(sa)
OSError: [Errno 99] Cannot assign requested address

During handling of the above exception, another exception occurred:

Traceback (most recent call last):
  File "/home/airflow/.local/lib/python3.7/site-packages/airflow/models/taskinstance.py", line 1829, in handle_failure
    self.email_alert(error, task)
  File "/home/airflow/.local/lib/python3.7/site-packages/airflow/models/taskinstance.py", line 2233, in email_alert
    send_email(task.email, subject, html_content_err)
  File "/home/airflow/.local/lib/python3.7/site-packages/airflow/utils/email.py", line 91, in send_email
    **kwargs,
  File "/home/airflow/.local/lib/python3.7/site-packages/airflow/utils/email.py", line 152, in send_email_smtp
    send_mime_email(e_from=mail_from, e_to=recipients, mime_msg=msg, conn_id=conn_id, dryrun=dryrun)
  File "/home/airflow/.local/lib/python3.7/site-packages/airflow/utils/email.py", line 270, in send_mime_email
    smtp_conn = _get_smtp_connection(smtp_host, smtp_port, smtp_timeout, smtp_ssl)
  File "/home/airflow/.local/lib/python3.7/site-packages/airflow/utils/email.py", line 317, in _get_smtp_connection
    else smtplib.SMTP(host=host, port=port, timeout=timeout)
  File "/usr/local/lib/python3.7/smtplib.py", line 251, in __init__
    (code, msg) = self.connect(host, port)
  File "/usr/local/lib/python3.7/smtplib.py", line 336, in connect
    self.sock = self._get_socket(host, port, self.timeout)
  File "/usr/local/lib/python3.7/smtplib.py", line 307, in _get_socket
    self.source_address)
  File "/usr/local/lib/python3.7/socket.py", line 728, in create_connection
    raise err
  File "/usr/local/lib/python3.7/socket.py", line 716, in create_connection
    sock.connect(sa)
OSError: [Errno 99] Cannot assign requested address
[2023-02-20T06:05:39.427+0000] {standard_task_runner.py:105} ERROR - Failed to execute job 552 for task process_json (Unable to locate credentials; 4104)
[2023-02-20T06:05:39.447+0000] {local_task_job.py:208} INFO - Task exited with return code 1
[2023-02-20T06:05:39.459+0000] {taskinstance.py:2578} INFO - 0 downstream tasks scheduled from follow-on schedule check
